<?xml version='1.0'?>

<robot name="Rover" xmlns:xacro="http://www.ros.org/wiki/xacro">

  <xacro:include filename="$(find rover_description)/urdf/rover.gazebo" />
  <xacro:include filename="$(find rover_description)/urdf/materials.xacro"/>
  
  
  <link name='base_footprint'>
    <pose>0 0 0 0 0 0</pose>

    <inertial>
      <mass value="15.0"/>
      <origin xyz="0.0 0 0.1" rpy=" 0 0 0"/>
      <inertia
          ixx="1000" 
          ixy="0" 
          ixz="0"
          iyy="1000" 
          iyz="0"
          izz="100"/>
    </inertial>

    <collision name='collision'>
      <origin xyz="0 0 0.15" rpy=" 0 0 0"/>
      <geometry>
        <box size= "1 0.5 0.35"/>
      </geometry>
    </collision>

    <visual name='base_footprint_visual'>
      <origin xyz="0 0 0.15" rpy=" 0 0 0"/>
      <geometry>
      
        <box size= "1 0.5 0.35"/>
      </geometry>
    </visual>
  </link>

  <link name="left_wheel_front">
    <collision name="collision">
      <origin xyz="0 0 0" rpy="0 1.5707 1.5707"/>
      <geometry>
        <cylinder radius="0.13" length="0.04"/>
      </geometry>
    </collision>

    <visual name="left_wheel_visual">
      <origin xyz="0 0 0" rpy="0 1.5707 1.5707"/>
      <geometry>
        <cylinder radius="0.13" length="0.04"/>
      </geometry>
    </visual>

    <inertial>
      <origin xyz="0 0 0" rpy="0 1.5707 1.5707"/>
      <mass value="5"/>
      <inertia
        ixx=".1" ixy="0.0" ixz="0.0"
        iyy=".1" iyz="0.0"
        izz=".1"/>
    </inertial>
  </link>

  <link name="right_wheel_front">
    <collision name="collision">
      <origin xyz="0 0 0" rpy="0 1.5707 1.5707"/>
      <geometry>
        <cylinder radius="0.13" length="0.04"/>
      </geometry>
    </collision>

    <visual name="right_wheel_visual">
      <origin xyz="0 0 0" rpy="0 1.5707 1.5707"/>
      <geometry>
        <cylinder radius="0.13" length="0.04"/>
      </geometry>
    </visual>

    <inertial>
      <origin xyz="0 0 0" rpy="0 1.5707 1.5707"/>
      <mass value="5"/>
      <inertia
        ixx=".1" ixy="0.0" ixz="0.0"
        iyy=".1" iyz="0.0"
        izz=".1"/>
    </inertial>
  </link>

  <link name="left_wheel_back">
    <collision name="collision">
      <origin xyz="0 0 0" rpy="0 1.5707 1.5707"/>
      <geometry>
        <cylinder radius="0.13" length="0.04"/>
      </geometry>
    </collision>

    <visual name="left_wheel_visual">
      <origin xyz="0 0 0" rpy="0 1.5707 1.5707"/>
      <geometry>
        <cylinder radius="0.13" length="0.04"/>
      </geometry>
    </visual>

    <inertial>
      <origin xyz="0 0 0" rpy="0 1.5707 1.5707"/>
      <mass value="5"/>
      <inertia
        ixx=".1" ixy="0.0" ixz="0.0"
        iyy=".1" iyz="0.0"
        izz=".1"/>
    </inertial>
  </link>

  <link name="right_wheel_back">
    <collision name="collision">
      <origin xyz="0 0 0" rpy="0 1.5707 1.5707"/>
      <geometry>
        <cylinder radius="0.13" length="0.04"/>
      </geometry>
    </collision>

    <visual name="right_wheel_visual">
      <origin xyz="0 0 0" rpy="0 1.5707 1.5707"/>
      <geometry>
        <cylinder radius="0.13" length="0.04"/>
      </geometry>
    </visual>

    <inertial>
      <origin xyz="0 0 0" rpy="0 1.5707 1.5707"/>
      <mass value="5"/>
      <inertia
        ixx=".1" ixy="0.0" ixz="0.0"
        iyy=".1" iyz="0.0"
        izz=".1"/>
    </inertial>
  </link>

  
  <joint type="continuous" name="left_wheel_front_hinge">
    <origin xyz="0.25 0.29 0" rpy="0 0 0"/>
    <child link="left_wheel_front"/>
    <parent link="base_footprint"/>
    <axis xyz="0 1 0" rpy="0 0 0"/>
    <limit effort="10000" velocity="1000"/>
    <joint_properties damping="1.0" friction="1.0"/>
  </joint>

  <joint type="continuous" name="right_wheel_front_hinge">
    <origin xyz="0.25 -0.29 0" rpy="0 0 0"/>
    <child link="right_wheel_front"/>
    <parent link="base_footprint"/>
    <axis xyz="0 1 0" rpy="0 0 0"/>
    <limit effort="10000" velocity="1000"/>
    <joint_properties damping="1.0" friction="1.0"/>
  </joint>

  <joint type="continuous" name="left_wheel_back_hinge">
    <origin xyz="-0.25 0.29 0" rpy="0 0 0"/>
    <child link="left_wheel_back"/>
    <parent link="base_footprint"/>
    <axis xyz="0 1 0" rpy="0 0 0"/>
    <limit effort="10000" velocity="1000"/>
    <joint_properties damping="1.0" friction="1.0"/>
  </joint>

  <joint type="continuous" name="right_wheel_back_hinge">
    <origin xyz="-0.25 -0.29 0" rpy="0 0 0"/>
    <child link="right_wheel_back"/>
    <parent link="base_footprint"/>
    <axis xyz="0 1 0" rpy="0 0 0"/>
    <limit effort="10000" velocity="1000"/>
    <joint_properties damping="1.0" friction="1.0"/>
  </joint>


  <joint name="sonar_front_joint" type="continuous">
      <axis xyz="0 0 1" />
      <origin rpy="0 0 0" xyz="0 0 0.35" />
      <parent link="base_footprint"/>
      <child link="base_sonar_front"/>
  </joint>

  <transmission name="sonar_trans" type="SimpleTransmission">
    <type>transmission_interface/SimpleTransmission</type>
    <actuator name="sonar_motor">
      <hardwareInterface>hardware_interface/EffortJointInterface</hardwareInterface>
    <mechanicalReduction>1</mechanicalReduction>
    </actuator>
    <joint name="sonar_front_joint">
      <hardwareInterface>hardware_interface/EffortJointInterface</hardwareInterface>
    </joint>
  </transmission>

  <link name="base_sonar_front">
      <collision>
        <origin xyz="0 0 0" rpy="0 0 0"/>
        <geometry>
          <box size="0.01 0.01 0.01"/>
        </geometry>
      </collision>
      <visual>
        <origin xyz="0 0 0" rpy="0 0 0"/>
        <geometry>
          <box size="0.01 0.01 0.01"/>
        </geometry>
      </visual>
      <inertial>
        <mass value="1e-5" />
        <origin xyz="0 0 0" rpy="0 0 0"/>
        <inertia ixx="10" ixy="0" ixz="0" iyy="10" iyz="0" izz="1" />
      </inertial>
  </link>

  <gazebo>
    <plugin name="gazebo_ros_control" filename="libgazebo_ros_control.so">
      <robotNamespace>/Rover</robotNamespace>
      <controlPeriod>0.01</controlPeriod>
      <!-- <legacyModeNS>false</legacyModeNS> -->
    </plugin>
  </gazebo>

  <link name="dummy">
  </link>
  <joint name="dummy_joint" type="fixed">
    <parent link="dummy"/>
    <child link="base_footprint"/>
  </joint>
</robot>

